{
  "nbformat": 4,
  "nbformat_minor": 0,
  "metadata": {
    "colab": {
      "name": "Welcome To Colaboratory",
      "provenance": [],
      "collapsed_sections": []
    },
    "kernelspec": {
      "display_name": "Python 3",
      "name": "python3"
    }
  },
  "cells": [
    {
      "cell_type": "code",
      "metadata": {
        "id": "D0rPZJK6aL4A",
        "outputId": "b50df047-e344-413a-e926-589b4d9c9df0",
        "colab": {
          "base_uri": "https://localhost:8080/"
        }
      },
      "source": [
        "!pip3 install -r ../../requirements.txt"
      ],
      "execution_count": 22,
      "outputs": [
        {
          "output_type": "stream",
          "text": [
            "Requirement already satisfied: pycuber in /usr/local/lib/python3.7/dist-packages (0.2.2)\n",
            "Traceback (most recent call last):\n",
            "  File \"/usr/local/lib/python3.7/dist-packages/pip/_vendor/pkg_resources/__init__.py\", line 3021, in _dep_map\n",
            "    return self.__dep_map\n",
            "  File \"/usr/local/lib/python3.7/dist-packages/pip/_vendor/pkg_resources/__init__.py\", line 2815, in __getattr__\n",
            "    raise AttributeError(attr)\n",
            "AttributeError: _DistInfoDistribution__dep_map\n",
            "\n",
            "During handling of the above exception, another exception occurred:\n",
            "\n",
            "Traceback (most recent call last):\n",
            "  File \"/usr/local/lib/python3.7/dist-packages/pip/_internal/cli/base_command.py\", line 180, in _main\n",
            "    status = self.run(options, args)\n",
            "  File \"/usr/local/lib/python3.7/dist-packages/pip/_internal/cli/req_command.py\", line 199, in wrapper\n",
            "    return func(self, options, args)\n",
            "  File \"/usr/local/lib/python3.7/dist-packages/pip/_internal/commands/install.py\", line 385, in run\n",
            "    conflicts = self._determine_conflicts(to_install)\n",
            "  File \"/usr/local/lib/python3.7/dist-packages/pip/_internal/commands/install.py\", line 515, in _determine_conflicts\n",
            "    return check_install_conflicts(to_install)\n",
            "  File \"/usr/local/lib/python3.7/dist-packages/pip/_internal/operations/check.py\", line 103, in check_install_conflicts\n",
            "    package_set, _ = create_package_set_from_installed()\n",
            "  File \"/usr/local/lib/python3.7/dist-packages/pip/_internal/operations/check.py\", line 45, in create_package_set_from_installed\n",
            "    package_set[name] = PackageDetails(dist.version, dist.requires())\n",
            "  File \"/usr/local/lib/python3.7/dist-packages/pip/_vendor/pkg_resources/__init__.py\", line 2736, in requires\n",
            "    dm = self._dep_map\n",
            "  File \"/usr/local/lib/python3.7/dist-packages/pip/_vendor/pkg_resources/__init__.py\", line 3023, in _dep_map\n",
            "    self.__dep_map = self._compute_dependencies()\n",
            "  File \"/usr/local/lib/python3.7/dist-packages/pip/_vendor/pkg_resources/__init__.py\", line 3033, in _compute_dependencies\n",
            "    reqs.extend(parse_requirements(req))\n",
            "  File \"/usr/local/lib/python3.7/dist-packages/pip/_vendor/pkg_resources/__init__.py\", line 3094, in parse_requirements\n",
            "    yield Requirement(line)\n",
            "  File \"/usr/local/lib/python3.7/dist-packages/pip/_vendor/pkg_resources/__init__.py\", line 3101, in __init__\n",
            "    super(Requirement, self).__init__(requirement_string)\n",
            "  File \"/usr/local/lib/python3.7/dist-packages/pip/_vendor/packaging/requirements.py\", line 113, in __init__\n",
            "    req = REQUIREMENT.parseString(requirement_string)\n",
            "  File \"/usr/local/lib/python3.7/dist-packages/pip/_vendor/pyparsing.py\", line 1943, in parseString\n",
            "    loc, tokens = self._parse(instring, 0)\n",
            "  File \"/usr/local/lib/python3.7/dist-packages/pip/_vendor/pyparsing.py\", line 1683, in _parseNoCache\n",
            "    loc, tokens = self.parseImpl(instring, preloc, doActions)\n",
            "  File \"/usr/local/lib/python3.7/dist-packages/pip/_vendor/pyparsing.py\", line 4069, in parseImpl\n",
            "    loc, exprtokens = e._parse(instring, loc, doActions)\n",
            "  File \"/usr/local/lib/python3.7/dist-packages/pip/_vendor/pyparsing.py\", line 1691, in _parseNoCache\n",
            "    retTokens = ParseResults(tokens, self.resultsName, asList=self.saveAsList, modal=self.modalResults)\n",
            "  File \"/usr/local/lib/python3.7/dist-packages/pip/_vendor/pyparsing.py\", line 555, in __init__\n",
            "    if self.__doinit:\n",
            "KeyboardInterrupt\n",
            "\n",
            "During handling of the above exception, another exception occurred:\n",
            "\n",
            "Traceback (most recent call last):\n",
            "  File \"/usr/local/bin/pip3\", line 8, in <module>\n",
            "    sys.exit(main())\n",
            "  File \"/usr/local/lib/python3.7/dist-packages/pip/_internal/cli/main.py\", line 71, in main\n",
            "    return command.main(cmd_args)\n",
            "  File \"/usr/local/lib/python3.7/dist-packages/pip/_internal/cli/base_command.py\", line 104, in main\n",
            "    return self._main(args)\n",
            "  File \"/usr/local/lib/python3.7/dist-packages/pip/_internal/cli/base_command.py\", line 212, in _main\n",
            "    logger.critical(\"Operation cancelled by user\")\n",
            "  File \"/usr/lib/python3.7/logging/__init__.py\", line 1425, in critical\n",
            "    self._log(CRITICAL, msg, args, **kwargs)\n",
            "  File \"/usr/lib/python3.7/logging/__init__.py\", line 1514, in _log\n",
            "    self.handle(record)\n",
            "  File \"/usr/lib/python3.7/logging/__init__.py\", line 1524, in handle\n",
            "    self.callHandlers(record)\n",
            "  File \"/usr/lib/python3.7/logging/__init__.py\", line 1586, in callHandlers\n",
            "    hdlr.handle(record)\n",
            "  File \"/usr/lib/python3.7/logging/__init__.py\", line 894, in handle\n",
            "    self.emit(record)\n",
            "  File \"/usr/lib/python3.7/logging/__init__.py\", line 1025, in emit\n",
            "    msg = self.format(record)\n",
            "  File \"/usr/local/lib/python3.7/dist-packages/pip/_internal/utils/logging.py\", line 208, in format\n",
            "    msg = super().format(record)\n",
            "  File \"/usr/lib/python3.7/logging/__init__.py\", line 869, in format\n",
            "    return fmt.format(record)\n",
            "  File \"/usr/local/lib/python3.7/dist-packages/pip/_internal/utils/logging.py\", line 130, in format\n",
            "    formatted = super().format(record)\n",
            "KeyboardInterrupt\n"
          ],
          "name": "stdout"
        }
      ]
    },
    {
      "cell_type": "code",
      "metadata": {
        "colab": {
          "base_uri": "https://localhost:8080/"
        },
        "id": "e3Lyd39MU8b0",
        "outputId": "8ec29c87-baaf-4ecf-ad32-6230cd78efea"
      },
      "source": [
        "!git clone https://github.com/ryersonburdick/sparse_rewards_transformer_games"
      ],
      "execution_count": 19,
      "outputs": [
        {
          "output_type": "stream",
          "text": [
            "Cloning into 'rubiks'...\n",
            "remote: Enumerating objects: 60, done.\u001b[K\n",
            "remote: Counting objects: 100% (60/60), done.\u001b[K\n",
            "remote: Compressing objects: 100% (59/59), done.\u001b[K\n",
            "remote: Total 60 (delta 25), reused 0 (delta 0), pack-reused 0\u001b[K\n",
            "Unpacking objects: 100% (60/60), done.\n"
          ],
          "name": "stdout"
        }
      ]
    }
  ]
}